Workbook
Name _r: [1]BL!$D$27
Name AB: 'L > ou = 24'!$D$66
Name AB: '[1]Arq L>24'!$C$57
Name AL: 'L > ou = 24'!$D$94
Name AL: '[1]Arq L>24'!$C$85
Name AnoConst: '[1]Dados de Entrada'!$D$17
Name Area1: #REF!
Name Area1: #REF!
Name Area1: #REF!
Name Area1: #REF!
Name Area1: #REF!
Name Area2: #REF!
Name Area2: #REF!
Name Area2: #REF!
Name Area2: #REF!
Name Area2: #REF!
Name AreaNav: '[1]Dados de Entrada'!$D$22
Name Art: '[1]Dados de Entrada'!$D$25
Name AS: #REF!
Name AS: #REF!
Name AS: #REF!
Name AS: #REF!
Name AS: #REF!
Name B: '[1]Dados de Entrada'!$D$33
Name Ca: '[1]Dados de Entrada'!$D$35
Name CargaCv: '[1]Dados de Entrada'!$D$53
Name Casco: '[1]Dados de Entrada'!$D$15
Name CentroDisco: #REF!
Name CentroDisco: #REF!
Name CentroDisco: #REF!
Name CentroDisco: #REF!
Name CentroDisco: #REF!
Name Classif: '[1]Dados de Entrada'!#REF!
Name Classif: '[1]Dados de Entrada'!#REF!
Name Classif: '[1]Dados de Entrada'!#REF!
Name Classif: '[1]Dados de Entrada'!#REF!
Name Classif: '[1]Dados de Entrada'!#REF!
Name Co: '[1]Dados de Entrada'!$D$34
Name Crea: '[1]Dados de Entrada'!$F$65
Name Data: '[1]Dados de Entrada'!$D$60
Name Dba: [1]BL!$D$68
Name Dmax: '[1]Dados de Entrada'!$D$41
Name Dmin: '[1]Dados de Entrada'!$D$42
Name Eng: '[1]Dados de Entrada'!$F$63
Name EspCarga: #REF!
Name EspCarga: #REF!
Name EspCarga: #REF!
Name EspCarga: #REF!
Name EspCarga: #REF!
Name Est: '[1]Dados de Entrada'!$D$14
Name hs: [1]BL!$D$74
Name IndCham: '[1]Dados de Entrada'!$D$24
Name LocalConst: '[1]Dados de Entrada'!$D$16
Name Lpp: '[2]Dados entrada'!$D$31
Name Lr: '[1]Dados de Entrada'!$D$30
Name Material: '[1]Dados de Entrada'!$D$18
Name MCP: '[1]Dados de Entrada'!$D$49
Name NMCP: '[1]Dados de Entrada'!$D$50
Name NomeArm: '[1]Dados de Entrada'!$D$13
Name NomeEmb: '[1]Dados de Entrada'!$D$12

Sheet Dados de Entrada
C1: DADOS DE ENTRADA – SISTEMA DE CERTIFICAÇÃO NORMAM-331/DPC
B5: Campo | C5: Valor (preencher aqui) | F5: Ajuda / Descritivo (como preencher)
B6: 1. INFORMAÇÕES GERAIS DA EMBARCAÇÃO (preencher primeiro) - Documento de Refrencia: Memorial Descritivo
A7: 1.1 | B7: Nome da Embarcação | C7: BJ | F7: Nome de registro/uso. Se não houver, informe o nome operacional.
A8: 1.2 | B8: Armador / Proprietário | C8: KLEDSON LUIS DOS SANTOS PEREIRA | F8: Razão social ou nome completo do proprietário/empresa responsável.
A9: 1.3 | B9: Numero de Inscrição | C9: Não Fornecido
B10: Numero de Inscrição | C10: Belém PA
A11: 1.4 | B11: Estaleiro Construtor | C11: KLEDSON LUIS DOS SANTOS PEREIRA
A12: 1.5 | B12: Número do Casco | C12: x-x-x
A13: 1.6 | B13: Local de Construção | C13: ABAETETUBA-PA
A14: 1.7 | B14: Ano de Construção/Alteração | C14: 2025
A15: 1.8 | B15: Material do Casco | C15: MADEIRA | F15: Ex.: aço, alumínio, madeira, fibra etc.
A16: 1.9 | B16: Tipo de Embarcação | C16: Carga Geral | F16: Ex.: empurrador, balsa, lancha, rebocador, ferry, draga etc.
A17: 1.10 | B17: Tipo de Serviço | C17: TRANSPORTE DE CARGA
A18: 1.11 | B18: Tipo de Navegação | C18: Interior | F18: Interior ou Mar Aberto
A19: 1.12 | B19: Área de Navegação | C19: Área 2 | F19: Area 1 ou Area 2
A20: 1.13 | B20: Indicatico de Chamada | C20: x-x-x | F20: Anatel
B21: 2. INFORMAÇÕES TÉCNICAS DA EMBARCAÇÃO - Docuemnto de Refrencia: Memorial Descritivo e Documentos Técnicos
A22: 1.13 | B22: Comprimento Total da embarcação - m | C22: 18.56 | F22: Informe em metros (m). Use valor do projeto, documento técnico ou medição.
A23: 1.14 | B23: Comprimento Total do Casco (Ct) - m | C23: 18.56 | F23: Informe em metros (m).
A24: 1.15 | B24: Comprimento entre (Lpp) - m | C24: 16.021 | F24: Informe em metros (m).
A25: 1.16 | B25: Pontal Moldado (P)- m | C25: 1.8
A26: 1.17 | B26: Boca Moldada (B) - m | C26: 3.9
A27: 1.18 | B27: Boca Maxima - m | C27: 3.9
A28: 1.19 | B28: Contorno (Co) = | C28: 6.6
A29: 1.20 | B29: Comprimento de Arqueação (Ca) = | C29: 16.82
A30: 1.21 | B30: Comprimento de Regra = | C30: 16.021
A31: 1.22 | B31: Calado Leve = | C31: 1.1 | E31: A vante
C32: 1.1 | E32: A ré
C33: =AVERAGE(C31:C32) -> 1.1 | E33: Médio
A34: 1.23 | B34: Calado Carregado = | C34: 1.5 | E34: A vante
C35: 1.5 | E35: A ré
C36: =AVERAGE(C34:C35) -> 1.5 | E36: Médio
A37: 1.24 | B37: Deslocamento Leve = | C37: 45.875
A38: 1.25 | B38: Deslocamento Carregado = | C38: 62.557
A39: 1.26 | B39: Porte Bruto = | C39: =C38-C37 -> 16.682
A40: 1.27 | B40: Número de Tripulantes: | C40: 3
A41: 1.28 | B41: N1 (No. de Passageiros em camarotes que tenham menos de oito beliches)= | C41: 0
A42: 1.29 | B42: N2 (No. dos demais Passageiros) = | C42: 0
B44: 3. INFORMAÇÕES PARA EMISSÃO DOS CERTIFICADOS
...

Sheet CONTROLE CERT.
F1: CONTROLE DE CERTIFICADOS - 2026
A7: Nº DO CERTIFICADO | F7: IDENTIFICAÇÃO DO CERTIFICADO | N7: NOME DA EMBARCAÇÃO | V7: DATA DA EMISSÃO
A8: 001/2026 | F8: AM-CSN-001/26 | N8: AMAZON | V8: 46174
A9: 002/2026 | F9: AM-CSN-002/26 | N9: AMAZON | V9: 46174
A10: 003/2026 | F10: AM-CSN-003/26 | N10: AMAZON | V10: 46174
A11: 004/2026 | F11: AM-CNARQ-004/26 | N11: AMAZON | V11: 46174
A12: 005/2026 | F12: AM-CNARQ-005/26 | N12: AMAZON | V12: 46174
A13: 006/2026 | F13: AM-CNARQ-006/26 | N13: AMAZON | V13: 46174
A14: 007/2026 | F14: AM-CNBL-007/26 | N14: AMAZON | V14: 46174
A15: 008/2026 | F15: AM-CNBL-008/26 | N15: AMAZON | V15: 46174
A16: 009/2026 | F16: AM-CNBL-009/26 | N16: AMAZON | V16: 46174

Sheet RV
H2: RELATÓRIO DE VISTORIA
H4: =CSN!H12 -> AMAZON NAVAL LTDA | U4: =CONCATENATE('Dados de Entrada'!B50,'Dados de Entrada'!C50,"/",'Dados de Entrada'!D50) -> AM-REL-V:1/26
H6: NOME DA EMBARCAÇÃO
H7: ='Dados de Entrada'!$C$7 -> BJ
B10: ARMADOR: | I10: ='Dados de Entrada'!C8 -> KLEDSON LUIS DOS SANTOS PEREIRA
B11: TIPO DE EMBARCAÇÃO: | I11: ='Dados de Entrada'!C16 -> Carga Geral
B12: N° de Inscrição: | I12: ='Dados de Entrada'!C9 -> Não Fornecido
B15: 1 - CARACTERÍSTICAS PRINCIPAIS DA EMBARCAÇÃO
B17: 1.1 - | D17: COMPRIMENTO TOTAL | L17: ='Dados de Entrada'!C22 -> 18.56 | O17: m
B18: 1.2 - | D18: BOCA MOLDADA | L18: ='Dados de Entrada'!C26 -> 3.9 | O18: m
B19: 1.3 - | D19: PONTAL MOLDADO | L19: ='Dados de Entrada'!C25 -> 1.8 | O19: m
B21: 2 - EXIGÊNCIAS
D22: VISTORIA DE ARQUEAÇÃO: | U22: ='Dados de Entrada'!C45 -> 45957
A23: ITEM | D23: DESCRIÇÃO | U23: REFERÊNCIA | Z23: VENCIMENTO
D24: O armador deverá apresentar a Título de Inscrição de Embarcação (TIE). | U24: NORMAM-202/DPC, Cap. 02, Item 2.1. | Z24: 46276
B25: 3 - OBSERVAÇÕES
A26: N° | D26: DESCRIÇÃO
A27: 1 | D27: Este relatório tem por objetivo evidenciar a vistoria de arqueação, com os planos e documentos técnicos elaborados pelo responsável José Leandro Cecim Pinto CREA N°: 151421424-5D/PA.
A29: --- | D29: ---
C35: ='Dados de Entrada'!C51 -> 46188
J46: VISTORIADOR NAVAL
J47: VICTAL DONANZAN NETO
J48: CREA: 5069476750 D-SP

Sheet L > ou = 24
B2: NOTAS PARA ARQUEAÇÃO DE EMBARCAÇÕES (L > ou = 24 m)
D5: NOME DA EMBARCAÇÃO
D6: ='Dados de Entrada'!C7 -> BJ
D9: =RV!H4 -> AMAZON NAVAL LTDA | G9: =CONCATENATE('Dados de Entrada'!B66,'Dados de Entrada'!C66,"/",'Dados de Entrada'!D66) -> AM-NARQ - 1/26
E11: =IF(C25>24," ","NÃO UTILIZAR - USAR A GUIA ''L < 24''") -> NÃO UTILIZAR - USAR A GUIA ''L < 24''
B12: 1. Características Gerais
B13: Nome da Embarcação: | D13: ='Dados de Entrada'!C7 -> BJ
B14: Armador: | D14: ='Dados de Entrada'!C8 -> KLEDSON LUIS DOS SANTOS PEREIRA
B15: Construtor: | D15: ='Dados de Entrada'!C11 -> KLEDSON LUIS DOS SANTOS PEREIRA
B16: ='[1]Dados de Entrada'!A15 -> Número do Casco: | D16: ='Dados de Entrada'!C12 -> x-x-x
B17: Material do Casco: | D17: ='Dados de Entrada'!C15 -> MADEIRA
B18: Tipo: | D18: ='Dados de Entrada'!C16 -> Carga Geral
B19: Classificação: | D19: ='Dados de Entrada'!C17 -> TRANSPORTE DE CARGA
B20: Porto de Inscrição: | D20: ='Dados de Entrada'!C10 -> Belém PA
B21: Data de Lançamento, Batimento da Quilha ou Construção: | G21: ='Dados de Entrada'!C14 -> 2025
B23: 2. Características do Casco
B24: Ct = | C24: ='Dados de Entrada'!C23 -> 18.56 | D24: P = | E24: ='Dados de Entrada'!C25 -> 1.8
B25: L = | C25: ='Dados de Entrada'!C30 -> 16.021 | D25: B = | E25: ='Dados de Entrada'!C26 -> 3.9
B26: Lpp = | C26: ='Dados de Entrada'!C24 -> 16.021
C28: AV = | D28: ='Dados de Entrada'!C31 -> 1.1 | I28: AV = | J28: ='Dados de Entrada'!C34 -> 1.5
B29: Calado Leve: | C29: AR = | D29: ='Dados de Entrada'!C32 -> 1.1 | E29: Calado Carregado: | I29: AR = | J29: ='Dados de Entrada'!C35 -> 1.5
C30: Médio = | D30: ='Dados de Entrada'!C33 -> 1.1 | I30: Médio = | J30: ='Dados de Entrada'!C36 -> 1.5
B33: 3. Tripulantes e Passageiros
B34: Número de Tripulantes = | D34: 0
B35: N1 (N° . de Passageiros em camarotes que tenham menos de oito beliches) = | J35: =IF('[3]Dados entrada'!H39>0,'[3]Dados entrada'!H39,IF('[3]Dados entrada'!F39>0,'[3]Dados entrada'!F39,IF('[3]Dados entrada'!F39=0,IF('[3]Dados entrada'!H39=0,"0","0")))) -> 0
B36: N2 (N° . dos demais Passageiros) = | E36: ='[3]Dados entrada'!D40 -> 0
B39: 4. Características Calculadas
B40: Deslocamentos:
B41: Carregado: | C41: ='Dados de Entrada'!C38 -> 62.557
B42: Leve: | C42: ='Dados de Entrada'!C37 -> 45.875
B43: Porte Bruto: | C43: ='Dados de Entrada'!C39 -> 16.682
B45: Espaços Fechados abaixo do Convés Superior | G45: =I113 -> 78.81
B46: Espaços Fechados acima do Convés Superior | G46: =I123 -> 92.87
B47: Espaços Excluídos | G47: =I132 -> 0
B48: V (Volume Total dos Espaços Fechados) | G48: =G45+G46-G47 -> 171.68 | I48: AB = | J48: =AB -> 42
B49: Vc (Volume dos Espaços de Carga) | G49: =I142 -> 54.7 | I49: AL = | J49: =AL -> 12
B51: ='Dados de Entrada'!C67 -> 46188
H54: VISTORIADOR NAVAL
H55: ANDRÉ ALVES BEZERRA
H56: CREA: 50615022D-SP 9622V-PA
...

Sheet CNARQ
B2: =CONCATENATE('Dados de Entrada'!B61,'Dados de Entrada'!C61,"/",'Dados de Entrada'!D61) -> CERTIFICADO AM-CNARQ - 1/26
I4: CERTIFICADO NACIONAL DE ARQUEAÇÃO | W4: =IF('Dados de Entrada'!H62="x","(CONDICIONAL)",IF('Dados de Entrada'!H63="x","(PROVISÓRIO)","")) -> (CONDICIONAL)
H6: REPÚBLICA FEDERATIVA DO BRASIL
H8: MARINHA DO BRASIL
H10: DIRETORIA DE PORTOS E COSTAS
H12: AMAZON NAVAL LTDA
B14: Nome da Embarcação | M14: N° de Inscrição | R14: Porto de Inscrição | W14: Data em que a quilha foi batida (ver nota)
B16: ='Dados de Entrada'!C7 -> BJ | M16: ='Dados de Entrada'!C9 -> Não Fornecido | R16: ='Dados de Entrada'!C10 -> Belém PA | W16: ='Dados de Entrada'!C64 -> 2025
B20: CARACTERÍSTICAS PRINCIPAIS
B22: Comprimento de Regra (m) | K22: Boca (m) | S22: Pontal moldado a meia-nau até o convés superior (m)
B24: ='Dados de Entrada'!C30 -> 16.021 | K24: ='Dados de Entrada'!C26 -> 3.9 | S24: ='Dados de Entrada'!C25 -> 1.8
B29: AS ARQUEAÇÕES DA EMBARCAÇÃO SÃO:
H31: ARQUAÇÃO BRUTA (AB): | O31: ='L > ou = 24'!J48 -> 42
H32: ARQUAÇÃO BRUTA (AB): | O32: ='L > ou = 24'!J49 -> 12
B34: Certifico que as arqueações desta embarcação foram determinadas de acordo com as disposições da Convenção Internacional sobre Medidas de Arqueações de Embarcações (1969) e das Normas da Autoridade Marítima para Embarcações Empregadas na Navegação Interior.
B38: NOTA: data na qual a quilha foi batida ou estágio equivalente de construção, ou data na qual o navio sofreu alterações ou modificações de maior vulto.
B44: ='Dados de Entrada'!C62 -> 46188
K55: Victal Donanzan Neto
K56: Tecnólogo Naval
K57: CREA: 5069476750 D-SP
B63: ESPAÇOS INCLUÍDOS NA ARQUEAÇÃO
B64: ARQUEAÇÃO BRUTA | O64: ARQUEAÇÃO LÍQUIDA
B66: NOME DO ESPAÇO | G66: LOCAL | K66: COMP. | O66: NOME DO ESPAÇO | T66: LOCAL | X66: COMP.
B67: Espaço fechado abaixo do convés:
B69: ='L > ou = 24'!I113 -> 78.81
B70: Espaço Fechado acima do convés:
B72: ='L > ou = 24'!I123 -> 92.87
O81: NÚMERO DE PASSAGEIROS
O82: Número total de passageiros em camarotes com até 8 beliches
B83: ESPAÇOS EXCLUÍDOS | O83: ='L > ou = 24'!J35 -> 0
B84: 0
O85: Número total dos demais passageiros
O86: ='L > ou = 24'!E36 -> 0
B88: um asterisco (*) deve ser feito naqueles espaços acima discriminados que sejam simultaneamente considerados espaços fechados e excluídos. | O88: CALADO MOLDADO
O89: ='Dados de Entrada'!C36 -> 1.5
B92: DATA E LOCAL DA ARQUEAÇÃO ORIGINAL: | M92: ABAETETUBA - PA 13/06/2026
B93: DATA E LOCAL DA ÚLTIMA REARQUEAÇÃO: | M93: - x -
B94: Observações:
B95: 1. Este Certificado Condicional foi emitido com base no Relatório de Vistorias n.º AM-REL-AP:001/26.
B96: 2. Vistoria de Arqueação para emissão do Certificado Nacional de Arqueação realizada em 13/06/2026 em Abaetetuba/PA.
...

Sheet NBL
B1: NOTAS PARA MARCAÇÃO DA BORDA LIVRE NACIONAL (Navegação Interior)
C4: NOME DA EMBARCAÇÃO
C5: ='Dados de Entrada'!C7 -> BJ
C8: =RV!H4 -> AMAZON NAVAL LTDA | F8: =CONCATENATE('Dados de Entrada'!B69,'Dados de Entrada'!C69,"/",'Dados de Entrada'!D69) -> AM-NBL - 100/26
A12: Nome da Embarcação: | C12: ='Dados de Entrada'!C7 -> BJ | J12: 70 | K12: 0.227 | L12: 95 | M12: 0.286
A13: Armador: | C13: ='Dados de Entrada'!C8 -> KLEDSON LUIS DOS SANTOS PEREIRA | J13: 75 | K13: 0.238 | L13: 100 | M13: 0.298
A14: Estaleiro Construtor: | C14: ='Dados de Entrada'!C11 -> KLEDSON LUIS DOS SANTOS PEREIRA | F14: Porto de Inscrição: | H14: ='Dados de Entrada'!C13 -> ABAETETUBA-PA | J14: 80 | K14: 0.25 | L14: 105 | M14: 0.311
A15: Tipo de Serviço: | C15: ='Dados de Entrada'!C17 -> TRANSPORTE DE CARGA | F15: Indicativo de Chamada: | H15: ='Dados de Entrada'!C20 -> x-x-x | J15: 85 | K15: 0.261 | L15: 110 | M15: 0.324
A16: Arqueação Bruta: | C16: ='[3]Dados entrada'!C55 -> 33 | F16: Ano de Construção/Alteração: | I16: ='Dados de Entrada'!C14 -> 2025 | J16: 90 | K16: 0.274 | L16: 115 | M16: 0.337
A19: 1. Caracterização da Área de Navegação:
A20: Descrição da Área de Operação: | D20: Navegação Interior
A22: Área de Navegação: | D22: ='Dados de Entrada'!C19 -> Área 2
A24: 2. Caracterização do Tipo de Embarcação:
A25: Descrição do Tipo de Embarcação: | D25: ='Dados de Entrada'!C16 -> Carga Geral
A27: Tipo de Embarcação: | C27: ( X ) | D27: A | E27: =IF('[3]Dados entrada'!F51="D","( X )","( )") -> ( ) | F27: B | G27: =IF('[3]Dados entrada'!H51="D","( X )","( )") -> ( ) | H27: C
C28: =IF('[3]Dados entrada'!D52="D","( X )","( )") -> ( ) | D28: D | E28: =IF('[3]Dados entrada'!D52="E","( X )","( )") -> ( ) | F28: E
A29: 3. Determinação do Fator de Flutuabilidade (r):
A30: - Comprimento de Regra (L) = | D30: ='Dados de Entrada'!C30 -> 16.021
A31: - Fator de Flutuabilidade (r) = | D31: 0.1846
A34: 4. Caracterização das Superestruturas Fechadas:
A35: a) Superestrutura 1:
A36: - Descrição: | B36: x-x-x-x
A38: - Comprimento Real da Superestrutura (S): | F38: 0
A39: - Boca da Embarcação (na metade do Comprimento S) (Bs): | F39: 0
A40: - Largura da Superestrutura (na metade do comprimento S) (b): | F40: 0
A41: - Comprimento Efetivo da Superestrutura (E) = (b/Bs) x S: | F41: =IF(F38>0,((F40/F39)*F38),0) -> 0
A42: - Altura da Superestrutura (he): | F42: 0
A43: - he2 / Hn (caso he2 / Hn > he, assumir he2 / Hn = he): | F43: =IF(F42/1.8>1,F42,F42*F42/1.8) -> 0
A44: - (he2 / Hn) x (E / L): | F44: =IF($D$30=0,0,F43*F41/$D$30) -> 0
A46: b) Superestrutura 2:
A47: - Descrição: | B47: x-x-x-x
A49: - Comprimento Real da Superestrutura (S): | F49: 0
A50: - Boca da Embarcação (na metade do Comprimento S) (Bs): | F50: 0
A51: - Largura da Superestrutura (na metade do comprimento S) (b): | F51: 0
A52: - Comprimento Efetivo da Superestrutura (E) = (b/Bs) x S: | F52: =IF(F49>0,((F51/F50)*F49),0) -> 0
A53: - Altura da Superestrutura (he): | F53: 0
A54: - he2 / Hn (caso he2 / Hn > he, assumir he2 / Hn = he): | F54: =IF(F53/1.8>1,F53,F53*F53/1.8) -> 0
A55: - (he2 / Hn) x (E / L): | F55: =IF($D$30=0,0,F54*F52/$D$30) -> 0
A57: c) Superestrutura 3:
A58: - Descrição: | B58: x-x-x-x
...

Sheet CNBL
B2: =CONCATENATE('Dados de Entrada'!B57,'Dados de Entrada'!C57,"/",'Dados de Entrada'!D57) -> CERTIFICADO AM-CNBL - 103/26
I4: CERTIFICADO NACIONAL DE BORDA LIVRE PARA NAVEGAÇÃO INTERIOR | W4: =IF('Dados de Entrada'!H58="x","(CONDICIONAL)",IF('Dados de Entrada'!H59="x","(PROVISÓRIO)","")) -> (CONDICIONAL)
H5: (EMITIDO DE ACORDO COM A NORMAM-202)
H7: REPÚBLICA FEDERATIVA DO BRASIL
H9: MARINHA DO BRASIL
H11: DIRETORIA DE PORTOS E COSTAS
H13: AMAZON NAVAL LTDA
B15: Nome da Embarcação | M15: N° de Inscrição | R15: Porto de Inscrição | W15: Arqueação Bruta
B17: ='Dados de Entrada'!C7 -> BJ | M17: ='Dados de Entrada'!C9 -> Não Fornecido | R17: ='Dados de Entrada'!C10 -> Belém PA | W17: ='L > ou = 24'!J48 -> 42
B21: Atividade ou Serviço: | K21: ='Dados de Entrada'!C17 -> TRANSPORTE DE CARGA
B22: Tipo de Embarcação: | K22: X | L22: A | O22: B | R22: C | U22: D | X22: E
B23: Área de Navegação Interior: | L23: Área 1 | O23: X | P23: Área 2
B25: DISTÂNCIA DA PARTE SUPERIOR DA LINHA DO CONVÉS ATÉ:
B26: CENTRO DO DISCO: | O26: =NBL!D146 -> 320 | Q26: mm
B27: MARCA DA LINHA DE CARGA PARA A ÁREA 1: | Q27: mm
B28: MARCA DA LINHA DE CARGA PARA A ÁREA 2: | O28: =NBL!D146 -> 320 | Q28: mm
B38: A ARESTA SUP. DA LINHA DO CONVÉS ESTÁ SITUADA A | O38: 0 | Q38: mm | S38: DA FACE SUPERIOR DO CONVÉS AO LADO.
B39: O CENTRO DO DISCO ESTÁ SITUADO A | K39: =NBL!E166 -> 25440 | M39: mm | O39: DO BICO DE PROA.
B40: ACRÉSCIMO PARA NAVEGAÇÃO EM ÁGUA SALGADA | C40: ACRÉSCIMO PARA NAVEGAÇÃO EM ÁGUA SALGADA - X - ABAIXO DO DISCO DE PLIMSOLL. | O40: 0 | Q40: mm | S40: ABAIXO DO DISCO DE PLIMSOLL.
B42: O PRESENTE CERTIFICADO É EXPEDIDO PARA ATESTAR QUE A EMBARCAÇÃO FOI VISTORIADA E QUE A SUA BORDA LIVRE E LINHA DE CARGA INDICADAS FORAM APOSTAS E SERÃO CONTROLADAS CONFORME AS DISPOSIÇÕES EM VIGOR.
B45: ='Dados de Entrada'!D59 -> 46248
B47: ='Dados de Entrada'!C53 -> 46062
K54: Aracelli Suzane Andrade Ferreira
K55: Engenheira Naval
K56: CREA: 22.482
B60: CONVALIDAÇÕES
B62: Este documento é para certificar que a vistoria requerida pela NORMAM-202/DPC foi efetuada e que a embarcação se encontrava de acordo com as prescrições relevantes da Norma.
B66: A REALIZAR | H66: ENTRE | L66: E | Q66: LUGAR E DATA DA REALIZAÇÃO | V66: VISTORIADOR
B67: 1ª VIST. ANUAL | L67: xx/xx/xxxx
B71: 2ª VIST. ANUAL | L71: xx/xx/xxxx
B75: 3ª VIST. ANUAL | L75: xx/xx/xxxx
B79: 4ª VIST. ANUAL | L79: xx/xx/xxxx
B84: Observações:
B85: 1. Este Certificado Condicional foi emitido com base no Relatório de Vistorias n.º AM-REL-AP:100/26.
B86: 2. Vistoria Flutuando para emissão do Certificado de Segurança da Navegação realizada em 08/02/65 em Belém/PA.
B113: ANEXO 6-A - NORMAM 202/DPC

Sheet CSN
B2: =CONCATENATE('Dados de Entrada'!B52,'Dados de Entrada'!C52,"/",'Dados de Entrada'!D52) -> CERTIFICADO AM-CSN - 101/26
H4: CERTIFICADO DE SEGURANÇA DA NAVEGAÇÃO | X4: =IF('Dados de Entrada'!H53="x","(CONDICIONAL)",IF('Dados de Entrada'!H54="x","(PROVISÓRIO)","")) -> (CONDICIONAL)
H6: REPÚBLICA FEDERATIVA DO BRASIL
H8: MARINHA DO BRASIL
H10: DIRETORIA DE PORTOS E COSTAS
H12: AMAZON NAVAL LTDA
B14: Nome da Embarcação | N14: N° de Inscrição | U14: Indicativo de Chamada
B16: ='Dados de Entrada'!C7 -> BJ | N16: ='Dados de Entrada'!C9 -> Não Fornecido | U16: ='Dados de Entrada'!C20 -> x-x-x
B20: Atividades ou Serviços | N20: Tipo de Embarcação | U20: Ano de Construção
B22: ='Dados de Entrada'!C16 -> Carga Geral | N22: ='Dados de Entrada'!C17 -> TRANSPORTE DE CARGA | U22: ='Dados de Entrada'!C14 -> 2025
B26: Comprimento (m) | H26: Arqueação Bruta | N26: Tipo de Navegação | U26: Área de Navegação
B28: ='Dados de Entrada'!C22 -> 18.56 | H28: ='L > ou = 24'!J48 -> 42 | P28: MAR ABERTO | W28: Longo Curso
W29: Cabotagem
W30: Apoio Marítimo
N31: X | P31: INTERIOR | W31: Área 1
P32: APOIO PORTUÁRIO | U32: X | W32: Área 2
B34: Fabricante, Modelo e Número do Motor | U34: Potência Propulsiva Total (kW)
B36: Embarcação sem Propulsão | U36: x-x-x-x
B40: Material do Casco | N40: Autorizado a Transportar Carga no Convés | U40: Quantidade Autorizada de Passageiros
B42: ='Dados de Entrada'!C15 -> MADEIRA | N42: X | P42: SIM | U42: 0 | X42: Vide verso
P44: NÃO
B47: A AMAZON LTDA certifica:
B48: Que a embarcação objeto de vistoria RENOVAÇÃO em conformidade com as disposições regulamentadas pela NORMAM 202 da Diretoria de Portos e Costas. | H48: ='Dados de Entrada'!C7 -> BJ | R48: foi objeto de vistoria de | X48: ='Dados de Entrada'!C54 -> EMISSÃO
B49: em conformidade com as disposições regulamentadas pela NORMAM 202 da Diretoria de Portos e Costas.
B50: A embarcação cumpre os requisitos de acessibilidade para o transporte coletivo aquaviário de passageiros. | W50: SIM
U51: X | W51: NÃO
B52: As vistorias evidenciaram que seu estado é satisfatório e que cumpre com as prescrições indicadas.
B54: O presente Certificado será válido até o vencimento indicado, estando sujeito a realização das vistorias anuais e intermediária que deverão ficar registradas entre as datas limites estabelecidas.
B57: ='Dados de Entrada'!C53 -> 46062
K64: Aracelli Suzane Andrade Ferreira
K65: Engenheira Naval
K66: CREA: 22.482
B70: CONVALIDAÇÕES
B71: ="Certifica-se que a embarcação "&'Dados de Entrada'!C7&" Foi objeto das vistorias a seguir estabelecidas, com resultado satisfatório, nos setores e datas indicadas, respectivamente." -> Certifica-se que a embarcação BJ Foi objeto das vistorias a seguir estabelecidas, com resultado satisfatório, nos setores e datas indicadas, respectivamente.
B74: A REALIZAR | H74: ENTRE | L74: E | Q74: LUGAR E DATA DA REALIZAÇÃO | V74: VISTORIADOR
B75: 1ª VIST. ANUAL | H75: =DATE(YEAR('Dados de Entrada'!$C$56)+1+ROW(A1)-1,MONTH('Dados de Entrada'!$C$56)-3,DAY('Dados de Entrada'!$C$56)) -> 46230 | L75: =DATE(YEAR('Dados de Entrada'!$C$56)+1+ROW(A1)-1,MONTH('Dados de Entrada'!$C$56)+3,DAY('Dados de Entrada'!$C$56)) -> 46414
B76: 2ª VIST. ANUAL | H76: =DATE(YEAR('Dados de Entrada'!$C$56)+1+ROW(A2)-1,MONTH('Dados de Entrada'!$C$56)-3,DAY('Dados de Entrada'!$C$56)) -> 46595 | L76: =DATE(YEAR('Dados de Entrada'!$C$56)+1+ROW(A2)-1,MONTH('Dados de Entrada'!$C$56)+3,DAY('Dados de Entrada'!$C$56)) -> 46779
B77: 3ª VIST. ANUAL | H77: =DATE(YEAR('Dados de Entrada'!$C$56)+1+ROW(A3)-1,MONTH('Dados de Entrada'!$C$56)-3,DAY('Dados de Entrada'!$C$56)) -> 46961 | L77: =DATE(YEAR('Dados de Entrada'!$C$56)+1+ROW(A3)-1,MONTH('Dados de Entrada'!$C$56)+3,DAY('Dados de Entrada'!$C$56)) -> 47145
B78: 4ª VIST. ANUAL | H78: =DATE(YEAR('Dados de Entrada'!$C$56)+1+ROW(A4)-1,MONTH('Dados de Entrada'!$C$56)-3,DAY('Dados de Entrada'!$C$56)) -> 47326 | L78: =DATE(YEAR('Dados de Entrada'!$C$56)+1+ROW(A4)-1,MONTH('Dados de Entrada'!$C$56)+3,DAY('Dados de Entrada'!$C$56)) -> 47510
B79: VISTORIA INTERMEDIÁRIA | H79: =DATE(YEAR('Dados de Entrada'!$C$56)+4,MONTH('Dados de Entrada'!$C$56),DAY('Dados de Entrada'!$C$56)) -> 47418 | L79: =DATE(YEAR('Dados de Entrada'!$C$56)+5,MONTH('Dados de Entrada'!$C$56),DAY('Dados de Entrada'!$C$56)) -> 47783
...

Sheet LC
K2: ANEXO 3-A - NORMAM 202/DPC
H4: MARINHA DO BRASIL
H6: DIRETORIA DE PORTOS E COSTAS
H9: AMAZON NAVAL LTDA
C11: LICENÇA DE CONSTRUÇÃO | S11: N°: X X X LC X X X X X - X X
C13: LICENÇA DE ALTERAÇÃO | S13: N°: X X X LA X X X X X - X X
C15: LICENÇA DE RECLASSIFICAÇÃO | S15: N°: X X X LR X X X X X - X X
B17: X | C17: LICENÇA DE CONSTRUÇÃO PARA EMBARCAÇÕES JÁ CONSTRUÍDAS (LCEC). DATA DO TÉRMINO DA CONSTRUÇÃO: 20206 | S17: N°: X X X EC X X X X X - 26
B21: NOME DA EMBARCAÇÃO: | H21: ='Dados de Entrada'!C7 -> BJ
B22: Tipo de Embarcação (NORMAM 202) | H22: ='Dados de Entrada'!C16 -> Carga Geral | O22: Comprimento Total: | U22: ='Dados de Entrada'!C22 -> 18.56
O23: Comprimento entre Perpendiculares: | U23: ='Dados de Entrada'!C24 -> 16.021
B24: Numero do Casco: | H24: ='Dados de Entrada'!C12 -> x-x-x
B25: Material do Casco | H25: ='Dados de Entrada'!C15 -> MADEIRA | O25: Boca Moldada: | U25: ='Dados de Entrada'!C26 -> 3.9
B26: Sociedade Classificadora / Certificadora | H26: Amazon Naval Ltda | O26: Pontal Moldado: | U26: ='Dados de Entrada'!C25 -> 1.8
O27: Calado Máximo: | U27: ='Dados de Entrada'!C36 -> 1.5
B28: Numero de Tripulantes: | H28: x-x-x
B29: Numero de Passageiros | H29: x-x-x | O29: Porte Bruto: | U29: ='Dados de Entrada'!C39 -> 16.682
B31: Tipo de Navegação | I31: Área de Navegação | P31: Atividade / Serviço | V31: Propulsão
D33: MAR ABERTO | K33: Longo Curso | R33: Passageiros | X33: Com Propulsão
K34: Cabotagem | R34: Carga
K35: Apoio Marítimo | R35: Rebocador / Empurrador | V35: X | X35: Sem Propulsão
B36: X | D36: INTERIOR | K36: Área 1 | M36: X | O36: Área 2 | R36: Pesca
D37: APOIO PORTUÁRIO | K37: Área 1 | O37: Área 2 | R37: Outras
B39: PROPRIETÁRIO / ARMADOR: | R39: CPF/CNPJ: | V39: xx-xxxxx-xxx
B41: Nome: | D41: ='Dados de Entrada'!C8 -> KLEDSON LUIS DOS SANTOS PEREIRA
B42: Endereço: | E42: Av Teste 01, Belém-PA | T42: CEP: | V42: x-x-x-x-
B44: ESTALEIRO / CONSTRUTOR: | R44: CPF/CNPJ: | V44: xx-xxxxx-xxx
B46: Nome: | D46: ='Dados de Entrada'!C11 -> KLEDSON LUIS DOS SANTOS PEREIRA
B47: Endereço: | E47: Av Teste 02, Belém-PA | T47: CEP: | V47: x-x-x-x-
B50: ='Dados de Entrada'!#REF! -> #REF!
K58: Aracelli Suzane Andrade Ferreira
K59: Engenheira Naval
K60: CREA: 22.482

Sheet LP
H4: MARINHA DO BRASIL
H6: DIRETORIA DE PORTOS E COSTAS
H9: AMAZON NAVAL LTDA
B11: LICENÇA PROVISÓRIA PARA INICIAR CONSTRUÇÃO / ALTERAÇÃO
B13: NÚMERO DA LICENÇA: XXX LP 0001/2026 - VÁLIDA ATÉ: 16/09/2026
B16: Concede-se autorização para início de construção da embarcação HP X do tipo EMPURRADOR, com número de casco - X -, com as seguintes características:
B20: A) | C20: Comprimento Total: | J20: ='Dados de Entrada'!C22 -> 18.56
B22: B) | C22: Boca Moldada: | J22: ='Dados de Entrada'!C26 -> 3.9
B24: C) | C24: Pontal Moldado: | J24: ='Dados de Entrada'!C25 -> 1.8
B26: D) | C26: Material do Casco: | J26: AÇO NAVAL
B29: ESTALEIRO / CONSTRUTOR: | R29: CPF/CNPJ: | V29: xx-xxxxx-xxx
B31: Nome: | D31: ='Dados de Entrada'!C11 -> KLEDSON LUIS DOS SANTOS PEREIRA
B32: Endereço: | E32: Av Teste 02, Belém-PA | T32: CEP: | V32: x-x-x-x-
B35: OBSERVAÇÕES / EXIGÊNCIAS:
B37: 1. A emissão da licença provisória não exime o interessado da obtenção da licença de construção definitiva, prevista no item 3.7.1. d), da NORMAM 202/DPC.
B40: 2. Licença Provisória para Iniciar Construção emitida com base no requerimento apresentado por tecnosolda serviços Navais Ltda, datado em 10/06/2026.
B46: ='Dados de Entrada'!#REF! -> #REF!
K54: Aracelli Suzane Andrade Ferreira
K55: Engenheira Naval
K56: CREA: 22.482

Sheet CHT
B2: =CONCATENATE('Dados de Entrada'!#REF!,'Dados de Entrada'!#REF!,"/",'Dados de Entrada'!#REF!) -> #REF!
B4: CERTIFICADO DE HOMOLOGAÇÃO DE EMPRESA OU PROFISSIONAL PRESTADOR DE SERVIÇOS
B5: (Emitido conforme Procedimento Interno de Homologação Técnica da AMAZON NAVAL LTDA)
B8: A AMAZON NAVAL LTDA., na qualidade de Organização Reconhecida / Entidade Certificadora, certifica que a empresa ou profissional abaixo identificado encontra-se HOMOLOGADO para execução de serviços técnicos conforme discriminado neste documento, no âmbito dos processos conduzidos pela certificadora, após análise documental, verificação técnica e atendimento aos critérios internos de homologação estabelecidos pela organização.
B10: EMPRESA / PROFISSIONAL HOMOLOGADO
B12: "PROFISSIONAL 1 HOMOLOGADO AMAZON" CPF: XXX-XXX-XXX-XX
B16: para execução da seguinte atividade técnica:
B18: MEDIÇÃO DE ESPESSURA (NORMAM 202/DPC)
B24: 1) A presente homologação reconhece que o profissional/empresa apresentou documentação técnica, qualificação profissional e requisitos mínimos compatíveis com a atividade homologada, conforme procedimento interno da AMAZON NAVAL LTDA.
B26: 2) A homologação não transfere ao terceiro a responsabilidade técnica final pelos processos conduzidos pela certificadora, permanecendo a aceitação técnica dos ensaios, relatórios e serviços sob responsabilidade da AMAZON NAVAL LTDA.
B28: 3) Esta homologação poderá ser suspensa, cancelada ou não renovada em caso de vencimento documental, perda de qualificação técnica, irregularidades identificadas ou descumprimento das normas aplicáveis.
B30: 4) Certificado emitido conforme Relatório de Homologação Técnica nº AM-REL-HT: 101/26
B34: ='Dados de Entrada'!#REF! -> #REF!
B36: ='Dados de Entrada'!#REF! -> #REF!
K45: Aracelli Suzane Andrade Ferreira
K46: Engenheira Naval
K47: CREA: 22.482
